Workbook

Sheet Metricas
B2: Cenário Mês Cheio
B3: # | C3: Mês | D3: Semana | E3: Dia
B4: Funcionários | C4: =Funcionários!C11 -> 12800 | D4: =C4/4 -> 3200 | E4: =D4/5 -> 640 | G4: =D6/5 -> 715.1
B5: Operação | C5: =Operação!D10 -> 1502 | D5: =C5/4 -> 375.5 | E5: =D5/5 -> 75.1
B6: TOTAL | C6: =SUM(C4:C5) -> 14302 | D6: =SUM(D4:D5) -> 3575.5 | E6: =SUM(E4:E5) -> 715.1
B8: Cenário Final de Semana
B9: # | C9: Mês | D9: Semana | E9: Dia
B10: Funcionários | C10: =Funcionários!G11 -> 8000 | D10: =C10/4 -> 2000 | E10: =D10/5 -> 400
B11: Operação | C11: =Operação!D10 -> 1502 | D11: =C11/4 -> 375.5 | E11: =D11/5 -> 75.1
B12: TOTAL | C12: =SUM(C10:C11) -> 9502 | D12: =SUM(D10:D11) -> 2375.5 | E12: =SUM(E10:E11) -> 475.1

Sheet Funcionários
A2: Cenário Mês Cheio | E2: Cenário Final de Semana
A3: Funcionarios | B3: v/dia | C3: valor total | E3: Funcionarios | F3: v/dia | G3: valor total
A4: Monique | B4: 100 | C4: =B4*22 -> 2200 | E4: Monique | F4: 100 | G4: =F4*12 -> 1200
A5: Jeniffer | B5: 100 | C5: =B5*8 -> 800 | E5: Jeniffer | F5: 100 | G5: 0
A6: Motoboy 1 | B6: 100 | C6: =B6*22 -> 2200 | E6: Motoboy 1 | F6: 100 | G6: =F6*12 -> 1200
A7: Motoboy 2 | B7: 100 | C7: =B7*22 -> 2200 | E7: Motoboy 2 | F7: 100 | G7: =F7*12 -> 1200
A8: Ricardo | B8: 100 | C8: =B8*22 -> 2200 | E8: Ricardo | F8: 100 | G8: =F8*12 -> 1200
A9: Layla | B9: 100 | C9: =B9*12 -> 1200 | E9: Layla | F9: 100 | G9: =F9*12 -> 1200
A10: Ana | B10: 60 | C10: 2000 | E10: Ana | F10: 60 | G10: 2000
A11: Total | C11: =SUM(C4:C10) -> 12800 | E11: Total | G11: =SUM(G4:G10) -> 8000
E14: DIFERENÇA | F14: =C11-G11 -> 4800

Sheet Operação
A1: Operação | B1: Valor | C1: Obs | D1: Mensal
A2: agua | B2: 50 | D2: =B2 -> 50
A3: energia | B3: 100 | D3: =B3 -> 100
A4: gas | B4: 120 | C4: 40 dias | D4: =3*24 -> 72
A5: internet | B5: 100 | D5: =B5 -> 100
A6: aluguel | B6: 800 | D6: =B6 -> 800
A7: Saco lixo | B7: 60 | D7: =B7 -> 60
A8: perfex | B8: 20 | C8: 10 por mês | D8: =B8*10 -> 200
A9: Sacola | B9: 80 | C9: 1,5 mês | D9: =B9*1.5 -> 120
D10: =SUM(D2:D9) -> 1502
D12: =D10/4 -> 375.5

Sheet Embalagens
A1: Nome | B1: qtd | C1: valor | D1: Total
A2: EMBALAGEM COMBINADO 01 | B2: 200 | C2: 1.59 | D2: =B2*C2 -> 318
A3: EMBALAGEM COMBINADO 02 | B3: 200 | C3: 1.99 | D3: =B3*C3 -> 398
A4: EMBALAGEM COMBINADO 03 | B4: 100 | C4: 3.25 | D4: =B4*C4 -> 325
A5: EMBALAGEM SUPER BIG BOAT Grande | B5: 40 | C5: 6 | D5: =B5*C5 -> 240
A6: EMBALAGEM SUPER BIG BOAT Media | B6: 40 | C6: 4.15 | D6: =B6*C6 -> 166
A7: EMBALAGEM TEMAKI 21X10 | B7: 100 | C7: 1 | D7: =B7*C7 -> 100
A8: EMBALAGEM TEMAKI BIOPLAS | B8: 100 | C8: 0.7 | D8: =B8*C8 -> 70
A9: EMBALAGEM RETANGULAR - SHIMEJI | B9: 24 | C9: =D9/B9 -> 0.75 | D9: 18

Sheet Insumos
A1: Insumos | B1: quantidade | C1: Unidade | D1: Valor | F1: Conversão para gramas | G1: Valor da grama
A2: Arroz | B2: 5 | C2: Kilograma | D2: 44 | F2: 5000 | G2: =D2/F2 -> 0.0088
A3: salmão | B3: 30 | C3: Kilograma | D3: 45 | F3: 1000 | G3: =D3/F3 -> 0.045
A4: alga | B4: 130 | C4: Grama | D4: 54.9 | F4: 130 | G4: =D4/F4 -> 0.42230769
A5: cebolinha | B5: 100 | C5: Gramas | D5: 6 | F5: 100 | G5: =D5/F5 -> 0.06
A6: creeamchese | B6: 1500G | C6: Grama | D6: 54.9 | F6: 1500 | G6: =D6/F6 -> 0.0366
A7: pepino | B7: 1 | C7: Kilograma | D7: 7 | F7: 1000 | G7: =D7/F7 -> 0.007
A8: gergelim | B8: 1 kl | C8: Kilograma | D8: 55 | F8: 1000 | G8: =D8/F8 -> 0.055
A9: Kani | B9: 200 g | C9: Grama | D9: 13 | F9: 200 | G9: =D9/F9 -> 0.065
A10: Skin | E10: Pele de salmão
A11: Couve | B11: 500 g | C11: Grama | D11: 8 | F11: 500 | G11: =D11/F11 -> 0.016
A12: Doritos | B12: 300g | C12: Grama | D12: 19 | F12: 300 | G12: =D12/F12 -> 0.063333333
A13: Shimeji | B13: 1 kl | C13: Kilograma | D13: 25 | F13: 1000 | G13: =D13/F13 -> 0.025
A14: Manteiga | B14: 500 g | C14: Grama | D14: 8 | F14: 500 | G14: =D14/F14 -> 0.016
A15: Leite | B15: 1 | C15: litro | D15: 5 | F15: 1000 | G15: =D15/F15 -> 0.005
A16: Ovo | B16: 20 | C16: unidade | D16: 18 | F16: 940 | G16: =D16/F16 -> 0.019148936
A17: Farinha de trigo | B17: 1 kl | C17: Kilograma | D17: 4 | F17: 1000 | G17: =D17/F17 -> 0.004
A18: Farinha panco | B18: 1 | C18: Kilograma | D18: 17.9 | F18: 1000 | G18: =D18/F18 -> 0.0179
A19: Geleia de pimenta | B19: 1.2 | C19: Kilograma | D19: 30.49 | F19: 1200 | G19: =D19/F19 -> 0.025408333
A20: Shoyo | B20: 20 | C20: litros | D20: 120 | F20: 23000 | G20: =D20/F20 -> 0.0052173913
A21: Alface | B21: 1 | D21: 6 | E21: 2 dias
A22: Cenoura | B22: 1 | C22: Kilograma | D22: 6 | E22: 4 Dias
A23: Manga | B23: 0 | D23: 0
A24: Oleo | B24: 1 | C24: litro | D24: 8 | E24: 1 dia
A25: Açucar | B25: 4 | E25: Por semana
A26: Sal | B26: 2 | E26: Mês

Sheet produto
A1: PESO EM GRAMAS
A2: Produtos | B2: Alga | C2: Creenchesse | D2: Cebolinha | E2: arroz | F2: Salmão | G2: Gergelin | H2: Couve | I2: Geleia de Pimenta | J2: Shimeji | K2: Manteiga | L2: Shoyu | M2: Ovo | N2: Leite | O2: farinha | P2: Completo Peso | Q2: Soma | R2: Valor venda | S2: Porção | T2: Valor unidade Vendida
A3: Temaki Filadelfia | B3: 1.3 | C3: 15 | D3: 3 | E3: 63 | F3: 100 | G3: 0 | H3: 0 | I3: 0 | J3: 0 | K3: 0 | L3: 0 | M3: 0 | N3: 0 | O3: 0 | P3: 180 | Q3: =B3+C3+D3+E3+F3+G3+H3+I3+J3+K3+L3+M3+N3+O3 -> 182.3 | R3: 26.9 | S3: 1 | T3: =R3/S3 -> 26.9
A4: Temaki Grelhado | B4: 1.3 | C4: 22 | D4: 3 | E4: 68 | F4: 74 | G4: 0 | H4: 0 | I4: 0 | J4: 0 | K4: 0 | L4: 0 | M4: 0 | N4: 0 | O4: 0 | P4: 159 | Q4: =B4+C4+D4+E4+F4+G4+H4+I4+J4+K4+L4+M4+N4+O4 -> 168.3 | R4: 26.9 | S4: 1 | T4: =R4/S4 -> 26.9
A5: Temaki salmão simples | B5: 1.3 | C5: 0 | D5: 0 | E5: 69 | F5: 100 | G5: 0 | H5: 0 | I5: 0 | J5: 0 | K5: 0 | L5: 0 | M5: 0 | N5: 0 | O5: 0 | P5: 181 | Q5: =B5+C5+D5+E5+F5+G5+H5+I5+J5+K5+L5+M5+N5+O5 -> 170.3 | R5: 24.9 | S5: 1 | T5: =R5/S5 -> 24.9
A6: Uramaki Salmão Simples | B6: 1.3 | C6: 0 | D6: 0 | E6: 143.7 | F6: 47 | G6: 1 | H6: 0 | I6: 0 | J6: 0 | K6: 0 | L6: 0 | M6: 0 | N6: 0 | O6: 0 | P6: 190 | Q6: =B6+C6+D6+E6+F6+G6+H6+I6+J6+K6+L6+M6+N6+O6 -> 193 | R6: 24.9 | S6: 8 | T6: =R6/S6 -> 3.1125
A7: Uramaki Filadelfia | B7: 1.3 | C7: 15 | D7: 3 | E7: 143.7 | F7: 47 | G7: 1 | H7: 0 | I7: 0 | J7: 0 | K7: 0 | L7: 0 | M7: 0 | N7: 0 | O7: 0 | P7: 208 | Q7: =B7+C7+D7+E7+F7+G7+H7+I7+J7+K7+L7+M7+N7+O7 -> 211 | R7: 25.9 | S7: 8 | T7: =R7/S7 -> 3.2375
A8: Uramaki Salmão Grelhado | B8: 1.3 | C8: 20 | D8: 3 | E8: =150-1.3 -> 148.7 | F8: 46 | G8: 1 | H8: 0 | I8: 0 | J8: 0 | K8: 0 | L8: 0 | M8: 0 | N8: 0 | O8: 0 | P8: 221 | Q8: =B8+C8+D8+E8+F8+G8+H8+I8+J8+K8+L8+M8+N8+O8 -> 220 | R8: 24.9 | S8: 8 | T8: =R8/S8 -> 3.1125
A9: Hossomaki | B9: 1.3 | C9: 0 | D9: 0 | E9: 104.7 | F9: 34 | G9: 0 | H9: 0 | I9: 0 | J9: 0 | K9: 0 | L9: 0 | M9: 0 | N9: 0 | O9: 0 | P9: 141 | Q9: =B9+C9+D9+E9+F9+G9+H9+I9+J9+K9+L9+M9+N9+O9 -> 140 | R9: 19.9 | S9: 8 | T9: =R9/S9 -> 2.4875
A10: Niguiri Salmão | B10: 0 | C10: 0 | D10: 0 | E10: 23 | F10: 7 | G10: 0 | H10: 0 | I10: 0 | J10: 0 | K10: 0 | L10: 0 | M10: 0 | N10: 0 | O10: 0 | P10: 30 | Q10: =B10+C10+D10+E10+F10+G10+H10+I10+J10+K10+L10+M10+N10+O10 -> 30 | R10: 32.9 | S10: 9 | T10: =R10/S10 -> 3.6555556
A11: Joe Salmão | B11: 0 | C11: 1 | D11: 0.5 | E11: 14 | F11: 14 | G11: 0 | H11: 0 | I11: 0 | J11: 0 | K11: 0 | L11: 0 | M11: 0 | N11: 0 | O11: 0 | P11: 28 | Q11: =B11+C11+D11+E11+F11+G11+H11+I11+J11+K11+L11+M11+N11+O11 -> 29.5 | R11: 29.9 | S11: 8 | T11: =R11/S11 -> 3.7375
A12: Joe Geleia de Pimenta | B12: 0 | C12: 4 | D12: 0.5 | E12: 14 | F12: 14 | G12: 0 | H12: 0 | I12: 0.5 | J12: 0 | K12: 0 | L12: 0 | M12: 0 | N12: 0 | O12: 0 | P12: 28 | Q12: =B12+C12+D12+E12+F12+G12+H12+I12+J12+K12+L12+M12+N12+O12 -> 33 | R12: 29.9 | S12: 8 | T12: =R12/S12 -> 3.7375
A13: Joe Crisp | B13: 0 | C13: 1 | D13: 0.5 | E13: 14 | F13: 14 | G13: 0 | H13: 1 | I13: 0 | J13: 0 | K13: 0 | L13: 0 | M13: 0 | N13: 0 | O13: 0 | P13: 28 | Q13: =B13+C13+D13+E13+F13+G13+H13+I13+J13+K13+L13+M13+N13+O13 -> 30.5 | R13: 29.9 | S13: 8 | T13: =R13/S13 -> 3.7375
A14: Sashimi | B14: 0 | C14: 0 | D14: 0 | E14: 0 | F14: 14 | G14: 0 | H14: 0 | I14: 0 | J14: 0 | K14: 0 | L14: 0 | M14: 0 | N14: 0 | O14: 0 | P14: 14 | Q14: =B14+C14+D14+E14+F14+G14+H14+I14+J14+K14+L14+M14+N14+O14 -> 14 | R14: 35.9 | S14: 10 | T14: =R14/S14 -> 3.59
A15: Shimeji | B15: 0 | C15: 0 | D15: 0 | E15: 0 | F15: 0 | G15: 0 | H15: 0 | I15: 0 | J15: 200 | K15: 10 | L15: 20 | M15: 0 | N15: 0 | O15: 0 | P15: 230 | Q15: =B15+C15+D15+E15+F15+G15+H15+I15+J15+K15+L15+M15+N15+O15 -> 230 | R15: 21.9 | S15: 1 | T15: =R15/S15 -> 21.9
A16: Temaki hot Filadelfia | B16: 1.3 | C16: 15 | D16: 3 | E16: 63 | F16: 100 | G16: 0 | H16: 0 | I16: 0 | J16: 0 | K16: 0 | L16: 0 | M16: 2.33 | N16: 2.33 | O16: 2.33 | P16: 187 | Q16: =B16+C16+D16+E16+F16+G16+H16+I16+J16+K16+L16+M16+N16+O16 -> 189.29 | R16: 28.9 | S16: 1 | T16: =R16/S16 -> 28.9
A17: Temaki hot Grelhado | B17: 1.3 | C17: 22 | D17: 3 | E17: 68 | F17: 74 | G17: 0 | H17: 0 | I17: 0 | J17: 0 | K17: 0 | L17: 0 | M17: 2.33 | N17: 2.33 | O17: 2.33 | P17: 166 | Q17: =B17+C17+D17+E17+F17+G17+H17+I17+J17+K17+L17+M17+N17+O17 -> 175.29 | R17: 28.9 | S17: 1 | T17: =R17/S17 -> 28.9
A18: Hotholl | B18: 1.3 | C18: 0 | D18: 0 | E18: 104.7 | F18: 34 | G18: 0 | H18: 0 | I18: 0 | J18: 0 | K18: 0 | L18: 0 | M18: 2.33 | N18: 2.33 | O18: 2.33 | P18: 148 | Q18: =B18+C18+D18+E18+F18+G18+H18+I18+J18+K18+L18+M18+N18+O18 -> 146.99 | R18: 24.9 | S18: 8 | T18: =R18/S18 -> 3.1125
A19: Hotholl Grelhado | B19: 1.3 | C19: 20 | D19: 3 | E19: =150-1.3 -> 148.7 | F19: 46 | G19: 1 | H19: 0 | I19: 0 | J19: 0 | K19: 0 | L19: 0 | M19: 0 | N19: 0 | O19: 0 | P19: 221 | Q19: =B19+C19+D19+E19+F19+G19+H19+I19+J19+K19+L19+M19+N19+O19 -> 220 | R19: 24.9 | S19: 8 | T19: =R19/S19 -> 3.1125
A20: Hotholl Premium | B20: 1.3 | C20: 20 | D20: 3 | E20: =150-1.3 -> 148.7 | F20: 46 | G20: 1 | H20: 0 | I20: 0 | J20: 0 | K20: 0 | L20: 0 | M20: 0 | N20: 0 | O20: 0 | P20: 221 | Q20: =B20+C20+D20+E20+F20+G20+H20+I20+J20+K20+L20+M20+N20+O20 -> 220 | R20: 24.9 | S20: 8 | T20: =R20/S20 -> 3.1125
A21: Joe Pepino (mesmo salmão) | B21: 0 | C21: 1 | D21: 0.5 | E21: 14 | F21: 14 | G21: 0 | H21: 0 | I21: 0 | J21: 0 | K21: 0 | L21: 0 | M21: 0 | N21: 0 | O21: 0 | P21: 28 | Q21: =B21+C21+D21+E21+F21+G21+H21+I21+J21+K21+L21+M21+N21+O21 -> 29.5 | R21: 29.9 | S21: 8 | T21: =R21/S21 -> 3.7375
A22: Niguiri Skin (mesmo que salmão) | B22: 0 | C22: 0 | D22: 0 | E22: 23 | F22: 7 | G22: 0 | H22: 0 | I22: 0 | J22: 0 | K22: 0 | L22: 0 | M22: 0 | N22: 0 | O22: 0 | P22: 30 | Q22: =B22+C22+D22+E22+F22+G22+H22+I22+J22+K22+L22+M22+N22+O22 -> 30 | R22: 32.9 | S22: 9 | T22: =R22/S22 -> 3.6555556
A23: Uramaki Premium (mesmo que filadelfia) | B23: 1.3 | C23: 15 | D23: 3 | E23: 143.7 | F23: 47 | G23: 1 | H23: 0 | I23: 0 | J23: 0 | K23: 0 | L23: 0 | M23: 0 | N23: 0 | O23: 0 | P23: 208 | Q23: =B23+C23+D23+E23+F23+G23+H23+I23+J23+K23+L23+M23+N23+O23 -> 211 | R23: 25.9 | S23: 8 | T23: =R23/S23 -> 3.2375
A24: Niguiri Salmão Premium (mesmo que salmão com duas gramas de salmão a mais | B24: 0 | C24: 0 | D24: 0 | E24: 23 | F24: 9 | G24: 0 | H24: 0 | I24: 0 | J24: 0 | K24: 0 | L24: 0 | M24: 0 | N24: 0 | O24: 0 | P24: 30 | Q24: =B24+C24+D24+E24+F24+G24+H24+I24+J24+K24+L24+M24+N24+O24 -> 32 | R24: 32.9 | S24: 9 | T24: =R24/S24 -> 3.6555556
A25: Temaki California (temaki de salmão simples) | B25: 1.3 | C25: 0 | D25: 0 | E25: 69 | F25: 100 | G25: 0 | H25: 0 | I25: 0 | J25: 0 | K25: 0 | L25: 0 | M25: 0 | N25: 0 | O25: 0 | P25: 181 | Q25: =B25+C25+D25+E25+F25+G25+H25+I25+J25+K25+L25+M25+N25+O25 -> 170.3 | R25: 24.9 | S25: 1 | T25: =R25/S25 -> 24.9
A26: Uramaki california (uramaki salmão simples) | B26: 1.3 | C26: 0 | D26: 0 | E26: 143.7 | F26: 47 | G26: 1 | H26: 0 | I26: 0 | J26: 0 | K26: 0 | L26: 0 | M26: 0 | N26: 0 | O26: 0 | P26: 190 | Q26: =B26+C26+D26+E26+F26+G26+H26+I26+J26+K26+L26+M26+N26+O26 -> 193 | R26: 24.9 | S26: 8 | T26: =R26/S26 -> 3.1125
A27: Uramaki Skin (uramaki salmão simples) | B27: 1.3 | C27: 0 | D27: 0 | E27: 143.7 | F27: 47 | G27: 1 | H27: 0 | I27: 0 | J27: 0 | K27: 0 | L27: 0 | M27: 0 | N27: 0 | O27: 0 | P27: 190 | Q27: =B27+C27+D27+E27+F27+G27+H27+I27+J27+K27+L27+M27+N27+O27 -> 193 | R27: 24.9 | S27: 8 | T27: =R27/S27 -> 3.1125
A30: Valor em Gramas em GRAMAS
A31: Produtos | B31: Alga | C31: Creenchesse | D31: Cebolinha | E31: arroz | F31: Salmão | G31: Gergelin | H31: Couve | I31: Geleia de Pimenta | J31: Shimeji | K31: Manteiga | L31: Shoyu | M31: Ovo | N31: Leite | O31: farinha | P31: Porção | Q31: Custo Produto | R31: Custo Porção | S31: Custo Unidade | T31: Venda Porção | U31: Venda Unidade | V31: Lucro por porção | W31: Lucro em Percentual
A32: Temaki Filadelfia | B32: =$B3*Insumos!$G$4 -> 0.549 | C32: =C3*Insumos!$G$6 -> 0.549 | D32: =D3*Insumos!$G$5 -> 0.18 | E32: =E3*Insumos!$G$2 -> 0.5544 | F32: =F3*Insumos!$G$3 -> 4.5 | G32: =G3*Insumos!$G$8 -> 0 | H32: =H3*Insumos!$G$11 -> 0 | I32: =I3*Insumos!$G$19 -> 0 | J32: =J3*Insumos!$G$13 -> 0 | K32: =K3*Insumos!$G$14 -> 0 | L32: =L3*Insumos!$G$20 -> 0 | M32: =M3*Insumos!$G$16 -> 0 | N32: =N3*Insumos!$G$15 -> 0 | O32: =O3*Insumos!$G$18 -> 0 | P32: 1 | Q32: =B32+C32+D32+E32+F32+G32+H32+I32+J32+K32+L32+M32+N32+O32 -> 6.3324 | R32: =Q32*P32 -> 6.3324 | S32: =Q32/P32 -> 6.3324 | T32: 26.9 | U32: =T32/P32 -> 26.9 | V32: =T32-Q32 -> 20.5676 | W32: =V32/T32 -> 0.7645948
A33: Temaki Grelhado | B33: =$B4*Insumos!$G$4 -> 0.549 | C33: =C4*Insumos!$G$6 -> 0.8052 | D33: =D4*Insumos!$G$5 -> 0.18 | E33: =E4*Insumos!$G$2 -> 0.5984 | F33: =F4*Insumos!$G$3 -> 3.33 | G33: =G4*Insumos!$G$8 -> 0 | H33: =H4*Insumos!$G$11 -> 0 | I33: =I4*Insumos!$G$19 -> 0 | J33: =J4*Insumos!$G$13 -> 0 | K33: =K4*Insumos!$G$14 -> 0 | L33: =L4*Insumos!$G$20 -> 0 | M33: =M4*Insumos!$G$16 -> 0 | N33: =N4*Insumos!$G$15 -> 0 | O33: =O4*Insumos!$G$18 -> 0 | P33: 1 | Q33: =B33+C33+D33+E33+F33+G33+H33+I33+J33+K33+L33+M33+N33+O33 -> 5.4626 | R33: =Q33*P33 -> 5.4626 | S33: =Q33/P33 -> 5.4626 | T33: 26.9 | U33: =T33/P33 -> 26.9 | V33: =T33-Q33 -> 21.4374 | W33: =V33/T33 -> 0.79692937
A34: Temaki salmão simples | B34: =$B5*Insumos!$G$4 -> 0.549 | C34: =C5*Insumos!$G$6 -> 0 | D34: =D5*Insumos!$G$5 -> 0 | E34: =E5*Insumos!$G$2 -> 0.6072 | F34: =F5*Insumos!$G$3 -> 4.5 | G34: =G5*Insumos!$G$8 -> 0 | H34: =H5*Insumos!$G$11 -> 0 | I34: =I5*Insumos!$G$19 -> 0 | J34: =J5*Insumos!$G$13 -> 0 | K34: =K5*Insumos!$G$14 -> 0 | L34: =L5*Insumos!$G$20 -> 0 | M34: =M5*Insumos!$G$16 -> 0 | N34: =N5*Insumos!$G$15 -> 0 | O34: =O5*Insumos!$G$18 -> 0 | P34: 1 | Q34: =B34+C34+D34+E34+F34+G34+H34+I34+J34+K34+L34+M34+N34+O34 -> 5.6562 | R34: =Q34*P34 -> 5.6562 | S34: =Q34/P34 -> 5.6562 | T34: 24.9 | U34: =T34/P34 -> 24.9 | V34: =T34-Q34 -> 19.2438 | W34: =V34/T34 -> 0.77284337
A35: Uramaki Salmão Simples | B35: =$B6*Insumos!$G$4 -> 0.549 | C35: =C6*Insumos!$G$6 -> 0 | D35: =D6*Insumos!$G$5 -> 0 | E35: =E6*Insumos!$G$2 -> 1.26456 | F35: =F6*Insumos!$G$3 -> 2.115 | G35: =G6*Insumos!$G$8 -> 0.055 | H35: =H6*Insumos!$G$11 -> 0 | I35: =I6*Insumos!$G$19 -> 0 | J35: =J6*Insumos!$G$13 -> 0 | K35: =K6*Insumos!$G$14 -> 0 | L35: =L6*Insumos!$G$20 -> 0 | M35: =M6*Insumos!$G$16 -> 0 | N35: =N6*Insumos!$G$15 -> 0 | O35: =O6*Insumos!$G$18 -> 0 | P35: 8 | Q35: =B35+C35+D35+E35+F35+G35+H35+I35+J35+K35+L35+M35+N35+O35 -> 3.98356 | R35: =Q35 -> 3.98356 | S35: =Q35/P35 -> 0.497945 | T35: 24.9 | U35: =T35/P35 -> 3.1125 | V35: =T35-Q35 -> 20.91644 | W35: =V35/T35 -> 0.84001767
A36: Uramaki Filadelfia | B36: =$B7*Insumos!$G$4 -> 0.549 | C36: =C7*Insumos!$G$6 -> 0.549 | D36: =D7*Insumos!$G$5 -> 0.18 | E36: =E7*Insumos!$G$2 -> 1.26456 | F36: =F7*Insumos!$G$3 -> 2.115 | G36: =G7*Insumos!$G$8 -> 0.055 | H36: =H7*Insumos!$G$11 -> 0 | I36: =I7*Insumos!$G$19 -> 0 | J36: =J7*Insumos!$G$13 -> 0 | K36: =K7*Insumos!$G$14 -> 0 | L36: =L7*Insumos!$G$20 -> 0 | M36: =M7*Insumos!$G$16 -> 0 | N36: =N7*Insumos!$G$15 -> 0 | O36: =O7*Insumos!$G$18 -> 0 | P36: 8 | Q36: =B36+C36+D36+E36+F36+G36+H36+I36+J36+K36+L36+M36+N36+O36 -> 4.71256 | R36: =Q36 -> 4.71256 | S36: =Q36/P36 -> 0.58907 | T36: 25.9 | U36: =T36/P36 -> 3.2375 | V36: =T36-Q36 -> 21.18744 | W36: =V36/T36 -> 0.81804788
A37: Uramaki Salmão Grelhado | B37: =$B8*Insumos!$G$4 -> 0.549 | C37: =C8*Insumos!$G$6 -> 0.732 | D37: =D8*Insumos!$G$5 -> 0.18 | E37: =E8*Insumos!$G$2 -> 1.30856 | F37: =F8*Insumos!$G$3 -> 2.07 | G37: =G8*Insumos!$G$8 -> 0.055 | H37: =H8*Insumos!$G$11 -> 0 | I37: =I8*Insumos!$G$19 -> 0 | J37: =J8*Insumos!$G$13 -> 0 | K37: =K8*Insumos!$G$14 -> 0 | L37: =L8*Insumos!$G$20 -> 0 | M37: =M8*Insumos!$G$16 -> 0 | N37: =N8*Insumos!$G$15 -> 0 | O37: =O8*Insumos!$G$18 -> 0 | P37: 8 | Q37: =B37+C37+D37+E37+F37+G37+H37+I37+J37+K37+L37+M37+N37+O37 -> 4.89456 | R37: =Q37 -> 4.89456 | S37: =Q37/P37 -> 0.61182 | T37: 24.9 | U37: =T37/P37 -> 3.1125 | V37: =T37-Q37 -> 20.00544 | W37: =V37/T37 -> 0.80343133
A38: Hossomaki | B38: =$B9*Insumos!$G$4 -> 0.549 | C38: =C9*Insumos!$G$6 -> 0 | D38: =D9*Insumos!$G$5 -> 0 | E38: =E9*Insumos!$G$2 -> 0.92136 | F38: =F9*Insumos!$G$3 -> 1.53 | G38: =G9*Insumos!$G$8 -> 0 | H38: =H9*Insumos!$G$11 -> 0 | I38: =I9*Insumos!$G$19 -> 0 | J38: =J9*Insumos!$G$13 -> 0 | K38: =K9*Insumos!$G$14 -> 0 | L38: =L9*Insumos!$G$20 -> 0 | M38: =M9*Insumos!$G$16 -> 0 | N38: =N9*Insumos!$G$15 -> 0 | O38: =O9*Insumos!$G$18 -> 0 | P38: 8 | Q38: =B38+C38+D38+E38+F38+G38+H38+I38+J38+K38+L38+M38+N38+O38 -> 3.00036 | R38: =Q38 -> 3.00036 | S38: =Q38/P38 -> 0.375045 | T38: 19.9 | U38: =T38/P38 -> 2.4875 | V38: =T38-Q38 -> 16.89964 | W38: =V38/T38 -> 0.84922814
A39: Niguiri Salmão | B39: =$B10*Insumos!$G$4 -> 0 | C39: =C10*Insumos!$G$6 -> 0 | D39: =D10*Insumos!$G$5 -> 0 | E39: =E10*Insumos!$G$2 -> 0.2024 | F39: =F10*Insumos!$G$3 -> 0.315 | G39: =G10*Insumos!$G$8 -> 0 | H39: =H10*Insumos!$G$11 -> 0 | I39: =I10*Insumos!$G$19 -> 0 | J39: =J10*Insumos!$G$13 -> 0 | K39: =K10*Insumos!$G$14 -> 0 | L39: =L10*Insumos!$G$20 -> 0 | M39: =M10*Insumos!$G$16 -> 0 | N39: =N10*Insumos!$G$15 -> 0 | O39: =O10*Insumos!$G$18 -> 0 | P39: 9 | Q39: =B39+C39+D39+E39+F39+G39+H39+I39+J39+K39+L39+M39+N39+O39 -> 0.5174 | R39: =Q39*P39 -> 4.6566 | S39: =R39/P39 -> 0.5174 | T39: 32.9 | U39: =T39/P39 -> 3.6555556 | V39: =T39-R39 -> 28.2434 | W39: =V39/T39 -> 0.85846201
A40: Joe Salmão | B40: =$B11*Insumos!$G$4 -> 0 | C40: =C11*Insumos!$G$6 -> 0.0366 | D40: =D11*Insumos!$G$5 -> 0.03 | E40: =E11*Insumos!$G$2 -> 0.1232 | F40: =F11*Insumos!$G$3 -> 0.63 | G40: =G11*Insumos!$G$8 -> 0 | H40: =H11*Insumos!$G$11 -> 0 | I40: =I11*Insumos!$G$19 -> 0 | J40: =J11*Insumos!$G$13 -> 0 | K40: =K11*Insumos!$G$14 -> 0 | L40: =L11*Insumos!$G$20 -> 0 | M40: =M11*Insumos!$G$16 -> 0 | N40: =N11*Insumos!$G$15 -> 0 | O40: =O11*Insumos!$G$18 -> 0 | P40: 8 | Q40: =B40+C40+D40+E40+F40+G40+H40+I40+J40+K40+L40+M40+N40+O40 -> 0.8198 | R40: =Q40*P40 -> 6.5584 | S40: =R40/P40 -> 0.8198 | T40: 29.9 | U40: =T40/P40 -> 3.7375 | V40: =T40-R40 -> 23.3416 | W40: =V40/T40 -> 0.78065552
A41: Joe Geleia de Pimenta | B41: =$B12*Insumos!$G$4 -> 0 | C41: =C12*Insumos!$G$6 -> 0.1464 | D41: =D12*Insumos!$G$5 -> 0.03 | E41: =E12*Insumos!$G$2 -> 0.1232 | F41: =F12*Insumos!$G$3 -> 0.63 | G41: =G12*Insumos!$G$8 -> 0 | H41: =H12*Insumos!$G$11 -> 0 | I41: =I12*Insumos!$G$19 -> 0.012704167 | J41: =J12*Insumos!$G$13 -> 0 | K41: =K12*Insumos!$G$14 -> 0 | L41: =L12*Insumos!$G$20 -> 0 | M41: =M12*Insumos!$G$16 -> 0 | N41: =N12*Insumos!$G$15 -> 0 | O41: =O12*Insumos!$G$18 -> 0 | P41: 8 | Q41: =B41+C41+D41+E41+F41+G41+H41+I41+J41+K41+L41+M41+N41+O41 -> 0.94230417 | R41: =Q41*P41 -> 7.5384333 | S41: =R41/P41 -> 0.94230417 | T41: 29.9 | U41: =T41/P41 -> 3.7375 | V41: =T41-R41 -> 22.361567 | W41: =V41/T41 -> 0.74787848
A42: Joe Crisp | B42: =$B13*Insumos!$G$4 -> 0 | C42: =C13*Insumos!$G$6 -> 0.0366 | D42: =D13*Insumos!$G$5 -> 0.03 | E42: =E13*Insumos!$G$2 -> 0.1232 | F42: =F13*Insumos!$G$3 -> 0.63 | G42: =G13*Insumos!$G$8 -> 0 | H42: =H13*Insumos!$G$11 -> 0.016 | I42: =I13*Insumos!$G$19 -> 0 | J42: =J13*Insumos!$G$13 -> 0 | K42: =K13*Insumos!$G$14 -> 0 | L42: =L13*Insumos!$G$20 -> 0 | M42: =M13*Insumos!$G$16 -> 0 | N42: =N13*Insumos!$G$15 -> 0 | O42: =O13*Insumos!$G$18 -> 0 | P42: 8 | Q42: =B42+C42+D42+E42+F42+G42+H42+I42+J42+K42+L42+M42+N42+O42 -> 0.8358 | R42: =Q42*P42 -> 6.6864 | S42: =R42/P42 -> 0.8358 | T42: 29.9 | U42: =T42/P42 -> 3.7375 | V42: =T42-R42 -> 23.2136 | W42: =V42/T42 -> 0.77637458
...

Sheet Combos
A1: Combos | B1: Peças | C1: Quantidade | D1: Valor custo
A2: Combo 1 | B2: EMBALAGEM COMBINADO 01 | C2: 1 | D2: =Embalagens!C2 -> 1.59
A3: Combo 2 | B3: EMBALAGEM COMBINADO 02 | C3: 1 | D3: =Embalagens!C3 -> 1.99
A4: Combo 3 | B4: EMBALAGEM COMBINADO 03 | C4: 1 | D4: =Embalagens!C4 -> 3.25
A5: Combo 3 | B5: Hossomaki Pepino | C5: 4
A6: Barca Akatsuky | B6: Hossomaki Salmão | C6: 20 | D6: =produto!$S$38*Combos!C2 -> 0.375045
A7: Barca casal | B7: Hossomaki Salmão | C7: 8 | D7: =produto!$S$38*Combos!C11 -> 1.50018
A8: Barca Premium | B8: Hossomaki Salmão | C8: 10 | D8: =produto!$S$38*Combos!C10 -> 1.50018
A9: Barca Salmão | B9: Hossomaki Salmão | C9: 4 | D9: =produto!$S$38*Combos!C8 -> 3.75045
A10: Combo 2 | B10: Hossomaki Salmão | C10: 4 | D10: =produto!$S$38*Combos!C5 -> 1.50018
A11: Combo 3 | B11: Hossomaki Salmão | C11: 4 | D11: =produto!$S$38*Combos!C6 -> 7.5009
A12: Combo 4 | B12: Hossomaki Salmão | C12: 8 | D12: =produto!$S$38*Combos!C9 -> 1.50018
A13: Combo 4 | B13: Hossomaki Salmão | C13: 8 | D13: =produto!$S$38*Combos!C13 -> 3.00036
A14: Barca Akatsuky | B14: Hossomaki Skin (salmão) | C14: 10 | D14: =produto!S38*Combos!C14 -> 3.75045
A15: Barca Akatsuky | B15: Hot Holl | C15: 10 | D15: =produto!$S$47*Combos!C18 -> 1.549167
A16: Barca casal | B16: Hot Holl | C16: 6 | D16: =produto!$S$47*Combos!C15 -> 3.8729175
A17: Combo 1 | B17: Hot Holl | C17: 3 | D17: =produto!$S$47*Combos!C17 -> 1.1618753
A18: Combo 2 | B18: Hot Holl | C18: 4 | D18: =produto!$S$47*Combos!C16 -> 2.3237505
A19: Combo 4 | B19: Hot Holl | C19: 8 | D19: =produto!$S$47*Combos!C19 -> 3.098334
A20: Barca Akatsuky | B20: Hot Premium | C20: 10 | D20: =produto!$S$49*Combos!C20 -> 6.1182
A21: Barca Premium | B21: Hot Premium | C21: 10 | D21: =produto!$S$49*Combos!C21 -> 6.1182
A22: Combo 5 | B22: Hot Premium | C22: 5 | D22: =produto!$S$49*Combos!C22 -> 3.0591
A23: Barca Akatsuky | B23: Joe Crisp | C23: 8 | D23: =produto!$S$42*Combos!C24 -> 3.3432
A24: Barca casal | B24: Joe Crisp | C24: 4 | D24: =produto!$S$42*Combos!C23 -> 6.6864
A25: Barca Premium | B25: Joe Crisp | C25: 6 | D25: =produto!$S$42*Combos!C25 -> 5.0148
A26: Barca Premium | B26: Joe Geleia de Pimenta | C26: 6 | D26: =produto!$S$41*Combos!C27 -> 3.7692167
A27: Combo 2 | B27: Joe Geleia de Pimenta | C27: 4 | D27: =produto!$S$41*Combos!C26 -> 5.653825
A28: Barca Akatsuky | B28: Joe Pepino | C28: 8 | D28: =produto!$S$50*Combos!C28 -> 0.8198
A29: Barca casal | B29: Joe Pepino | C29: 4 | D29: =produto!$S$50*Combos!C29 -> 0.4099
A30: Combo 1 | B30: Joe Pepino | C30: 3 | D30: =produto!$S$50*Combos!C30 -> 0.307425
A31: Combo 3 | B31: Joe Pepino | C31: 4 | D31: =produto!$S$50*Combos!C31 -> 0.4099
A32: Barca Akatsuky | B32: Joe Salmão | C32: 8 | D32: =produto!$S$40*Combos!C33 -> 3.2792
A33: Barca casal | B33: Joe Salmão | C33: 4 | D33: =produto!$S$40*Combos!C34 -> 4.9188
A34: Barca Premium | B34: Joe Salmão | C34: 6 | D34: =produto!$S$40*Combos!C32 -> 6.5584
A35: Barca Salmão | B35: Joe Salmão | C35: 3 | D35: =produto!$S$40*Combos!C35 -> 2.4594
A36: Combo 5 | B36: Joe Salmão Crispy | C36: 4 | D36: =produto!$S$42*Combos!C36 -> 3.3432
A37: Barca Akatsuky | B37: Niguiri Salmão | C37: 10 | D37: =produto!$S$39*Combos!C40 -> 1.5522
A38: Barca Premium | B38: Niguiri Salmão | C38: 10 | D38: =produto!$S$39*Combos!C38 -> 5.174
A39: Barca Salmão | B39: Niguiri Salmão | C39: 6 | D39: =produto!$S$39*Combos!C41 -> 1.0348
A40: Combo 1 | B40: Niguiri Salmão | C40: 3 | D40: =produto!$S$39*Combos!C37 -> 5.174
...

Sheet Calculo de COMBOS
A1: Rótulos de Linha | B1: Soma de Valor custo | C1: Combos | D1: Custo | E1: Preço de Venda | F1: Lucro | G1: Lucro em Percentual
A2: Barca Akatsuky | B2: 78.083056 | C2: Barca Akatsuky | D2: 78.083056 | E2: 349.9 | F2: =E2-D2 -> 271.81694 | G2: =F2/E2 -> 0.77684179
A3: Barca casal | B3: 23.173291 | C3: Barca casal | D3: 23.173291 | E3: 119.9 | F3: =E3-D3 -> 96.726709 | G3: =F3/E3 -> 0.80672819
A4: Barca Premium | B4: 49.408219 | C4: Barca Premium | D4: 49.408219 | E4: 216.9 | F4: =E4-D4 -> 167.49178 | G4: =F4/E4 -> 0.77220738
A5: Barca Salmão | B5: 18.85646 | C5: Barca Salmão | D5: 18.85646 | E5: 95.9 | F5: =E5-D5 -> 77.04354 | G5: =F5/E5 -> 0.80337372
A6: Combo 1 | B6: 8.3369603 | C6: Combo 1 | D6: 8.3369603 | E6: 45.9 | F6: =E6-D6 -> 37.56304 | G6: =F6/E6 -> 0.81836688
A7: Combo 2 | B7: 13.083699 | C7: Combo 2 | D7: 13.083699 | E7: 79.9 | F7: =E7-D7 -> 66.816301 | G7: =F7/E7 -> 0.83624908
A8: Combo 3 | B8: 13.957838 | C8: Combo 3 | D8: 13.957838 | E8: 58.9 | F8: =E8-D8 -> 44.942162 | G8: =F8/E8 -> 0.76302483
A9: Combo 4 | B9: 29.010414 | C9: Combo 4 | D9: 29.010414 | E9: 112.9 | F9: =E9-D9 -> 83.889586 | G9: =F9/E9 -> 0.74304328
A10: Combo 5 | B10: 17.05036 | C10: Combo 5 | D10: 17.05036 | E10: 95.9 | F10: =E10-D10 -> 78.84964 | G10: =F10/E10 -> 0.82220688
A11: (vazio)
A12: Total Geral | B12: 250.9603
